Workbook

Sheet Current
A1: Wordpress ID | B1: Sort Order | C1: Title | D1: Location | E1: Size (Sq. Ft) | F1: Role | G1: Designed By | H1: Architecture by | I1: Category | J1: Sub-Category / Filter | K1: Link
A2: 439 | B2: 1 | C2: Boqueria Restaurant | D2: Midtown | E2: 10500 | F2: General Contractor | G2: Studio Razavi | H2: Bill White | I2: Commercial | J2: Restaurant | K2: https://www.streamlineusa.com/commercial/boqueria-restaurant/
A3: 552 | B3: 1 | C3: Duane Street Penthouse | D3: Tribeca | E3: 4000 | F3: General Contractor | G3: Dean Winters and Diana Gomez | H3: SWA Architecture | I3: Residential | K3: https://www.streamlineusa.com/residential/duane-street-penthouse/
B4: 1 | C4: Bad Roman 10 Columbus Mall | D4: Upper West Side | E4: 12500 | F4: General Contractor | G4: Michael Stillman | H4: GRT Architects LLP | I4: Commercial
A5: 436 | B5: 2 | C5: Sugarcane Raw Bar And Grill | D5: Brooklyn | E5: 12500 | F5: General Contractor + Millwork | G5: CetraRuddy Design | H5: Lawrence Jones Architecture | I5: Commercial | J5: Restaurant | K5: https://www.streamlineusa.com/commercial/sugar-cane-raw-bar-and-grill/
A6: 2306 | B6: 2 | C6: e64th St Townhouse | D6: Lenox Hill | E6: 3800 | F6: General Contractor | G6: Virginia Tupker Interiors | H6: MZA Architecture | I6: Residential | K6: https://www.streamlineusa.com/residential/e64-st-townhouse/
A7: 433 | B7: 3 | C7: Grand Ole Opry City Stage | D7: Times Square | E7: 22000 | F7: Construction Manager | G7: Morris Nathanson Interior Design | H7: SWA architecture | I7: Commercial | K7: https://www.streamlineusa.com/commercial/grand-ole-opry-city-stage/
A8: 570 | B8: 3 | C8: 69th St Townhouse | D8: Upper West Side | E8: 6000 | F8: General Contractor + Millwork | G8: Fury Design | H8: Adi Gershoni | I8: Residential | K8: https://www.streamlineusa.com/residential/69th-st-townhouse/
B9: 3 | C9: 700 Park Ave | D9: Upper East Side | E9: 2100 | F9: General Contractor | G9: Griffin Design Studios Jorge Porta | H9: Griffin Design Studios Jorge Porta | I9: Residential | K9: Need copy, images are too low res. you can tell by the featured photo
A10: 506 | B10: 4 | C10: Spring Studios, Spring Place | D10: Tribeca | E10: 15000 | F10: General Contractor | G10: Bluarch Design | H10: Antonio DiOronzo | I10: Commercial | K10: https://www.streamlineusa.com/commercial/spring-studios-spring-place/
A11: 531 | B11: 4 | C11: St. Lukes Place townhouse | D11: West Village | E11: 5500 | F11: General Contractor | G11: Barlis Wedlick | H11: Barlis Wedlick | I11: Residential | K11: https://www.streamlineusa.com/residential/st-lukes-place-townhouse/
B12: 4 | C12: Ketchy Shubby | D12: Soho | E12: 7500 | F12: General Contractor | G12: Dimitri Hyacinthe Interiors | H12: RIP Consulting Steve Salveson | I12: Commercial
A13: 517 | B13: 5 | C13: Hudson Street Penthouse | D13: Tribeca | E13: 3500 | F13: Millwork + Finishes | G13: Alex May | H13: 212Box Architecture | I13: Residential | K13: https://www.streamlineusa.com/residential/hudson-street-penthouse/
A14: 555 | B14: 5 | C14: Indeed Corporate Office Suite | D14: Midtown | E14: 36000 | F14: Carpentry + Millwork | G14: Indeed corporate | I14: Commercial | K14: https://www.streamlineusa.com/commercial/indeed-corporate-office-suite/
B15: 5 | C15: Momofuku noodle 171 1st ave | D15: East Side | E15: 4200 | F15: General Contractor | G15: Richard Lewis | H15: Richard Lewis | I15: Commercial | J15: Restaurant | K15: Need copy
A16: 561 | B16: 6 | C16: KITH | D16: NoHo | E16: 7500 | F16: General Contractor | G16: Snarkitecture | H16: Snarkitecture | I16: Commercial | J16: Retail | K16: https://www.streamlineusa.com/commercial/kith/
A17: 2842 | B17: 6 | C17: Riverside Drive Apartment | D17: Morningside Heights | E17: 2900 | F17: General Contractor | G17: Samantha Orley Interiors | H17: MZA Architecture | I17: Residential | K17: https://www.streamlineusa.com/residential/riverside-drive-apartment/
A18: 546 | B18: 7 | C18: Versa at the Marriott Renaissance | D18: Herald Square | E18: 18000 | F18: Construction Manager | G18: Celano Design | H18: SRAA architecture | I18: Commercial | K18: https://www.streamlineusa.com/commercial/versa-marriott/
A19: 2847 | B19: 7 | C19: WARREN ST APT | D19: Tribeca | E19: 2600 | F19: General Contractor | G19: Current Interiors | H19: Michael Tower Architecture | I19: Residential | K19: https://www.streamlineusa.com/residential/warren-st-apt/
A20: new photos coming | B20: 7 | C20: 40 e66th st | D20: Upper East Side | E20: 2200 | F20: General Contractor | G20: Cetra Ruddy | H20: Cetra Ruddy | I20: Residential | K20: Need pics and copy
A21: 491 | B21: 8 | C21: Kat & Theo | D21: Flatiron District | E21: 2300 | F21: General Contractor + Millwork | G21: Aviva Collective | H21: Claudia Pinto | I21: Commercial | K21: https://www.streamlineusa.com/commercial/kat-theo/
A22: 2504 | B22: 8 | C22: 12th st townhouse | D22: Greenwich Village | E22: 7000 | F22: Carpentry Millwork + Finishes | G22: Elisabeth de Kergorlay | H22: Jacobson Sonoba | I22: Residential | K22: https://www.streamlineusa.com/residential/12th-st-townhouse-greenwich-village/
A23: 509 | B23: 9 | C23: Burger & Lobster | D23: Bryant Park | E23: 8500 | F23: General Contractor + Millwork | G23: MZA Architecture | H23: Design LSM | I23: Commercial | J23: Restaurant | K23: https://www.streamlineusa.com/commercial/burger-lobster/
A24: 567 | B24: 9 | C24: Horatio St. Townhouse | D24: Meat Packing District | E24: 3200 | F24: General Contractor + Millwork | G24: Tersigni Palachek Design | H24: David Bae Architect | I24: Residential | K24: https://www.streamlineusa.com/residential/horatio-st-townhouse/
A25: 512 | B25: 10 | C25: Momofuku KO | D25: Bowery | E25: 4500 | F25: General Contractor | G25: Richard Lewis design | H25: Richard Lewis Architecture | I25: Commercial | J25: Restaurant | K25: https://www.streamlineusa.com/commercial/momofuku-ko/
A26: 1835 | B26: 10 | C26: Lexington Ave Townhouse | D26: Upper East Side | E26: 4500 | F26: General Contractor | G26: Salvatore LaRosa | H26: B5 Studio Architects | I26: Residential | K26: https://www.streamlineusa.com/residential/lexington-ave-townhouse/
A27: 537 | B27: 11 | C27: West 23rd St. Townhouse | D27: Chelsea | E27: 2200 | F27: General Contractor + Millwork | G27: Tersigni Palachek Design | H27: Tersigni Palachek Design | I27: Residential | K27: https://www.streamlineusa.com/residential/west-23rd-townhouse-2/
A28: 549 | B28: 11 | C28: Gunter-Seeger | D28: West Village | E28: 3300 | F28: General Contractor + Millwork | G28: AWI Interiors | H28: MZA Architecture | I28: Commercial | K28: https://www.streamlineusa.com/commercial/gunter-seeger/
A29: 2850 | B29: 12 | C29: Hudson Yards Mall | D29: Hudson Yards | E29: 3500 | F29: General Contractor | G29: Jack Mazzolla | I29: Commercial | K29: https://www.streamlineusa.com/commercial/hudson-yards-mall/
A30: 2860 | B30: 12 | C30: Wyckoff Townhouse | D30: Boerum Hill | E30: 4500 | F30: General Contractor | G30: Current Interiors | H30: Rachel Kane & Xandro Aventajado | I30: Residential | K30: https://www.streamlineusa.com/residential/wyckoff-townhouse/
A31: 443 | B31: 13 | C31: Mint Kitchen Restaurant | D31: West Village | E31: 4000 | F31: General Contractor | G31: Creme | H31: MZA Architecture | I31: Commercial | K31: https://www.streamlineusa.com/commercial/mint-kitchen-restaurant/
A32: 523 | B32: 13 | C32: Madison Ave Duplex | D32: Murray Hill | E32: 3400 | F32: General Contractor + Millwork | G32: Lynch Eisinger Design | H32: Christian Lynch | I32: Residential | K32: https://www.streamlineusa.com/residential/madison-ave-duplex-2/
A33: 494 | B33: 14 | C33: ViVVI Daycare Tribeca | D33: Tribeca | E33: 10000 | F33: General Contractor | G33: Eleven of Eleven architecture | H33: Carol Gretter | I33: Commercial | J33: Office (mixed use) | K33: https://www.streamlineusa.com/commercial/vivvi-daycare-tribeca/
A34: 520 | B34: 14 | C34: Tribeca Loft | D34: Tribeca | E34: 2500 | F34: Millwork + Finishes | G34: Bore | I34: Residential | K34: https://www.streamlineusa.com/residential/tribeca-loft/
A35: 540 | B35: 15 | C35: e63rd st Penthouse | D35: Lenox Hill | E35: 1700 | F35: General Contractor + Millwork | G35: Jennifer Aderholdt Design | H35: SWA Architecture | I35: Residential | K35: https://www.streamlineusa.com/residential/e63-st-penthouse/
A36: 2853 | B36: 15 | C36: Vivvi Daycare Hudson Yards | D36: Hudson Yards | E36: 7500 | F36: General Contractor | G36: Eleven of Eleven design | H36: Carol Gretter Elven of Eleven architecture | I36: Commercial | J36: Office (mixed use) | K36: https://www.streamlineusa.com/commercial/vivvi-daycare-hudson-yards/
A37: 2396 | B37: 16 | C37: 84th st townhouse | D37: Jackson Heights | E37: 2200 | F37: General Contractor | G37: Nathalie Akiya Design | H37: SWA Architecture | I37: Residential | K37: https://www.streamlineusa.com/residential/84th-st-townhouse/
A38: 2520 | B38: 16 | C38: Haus Nightclub | D38: Lower Manhattan | E38: 5500 | F38: General Contractor | G38: John Rawlins Design | H38: SWA Architecture | I38: Commercial | K38: https://www.streamlineusa.com/commercial/haus-nightclub/
A39: 1907 | B39: 17 | C39: Sullivan St duplex | D39: SOHO | E39: 6000 | F39: Millwork + Finishes | G39: Butter and Eggs Design | H39: Michael Tower Architecture | I39: Residential | K39: https://www.streamlineusa.com/residential/sullivan-st-duplex-2/
B40: 17 | C40: Mexicue | D40: NoHo | E40: 3500 | F40: General Contractor | G40: Treehouse Designs | H40: SWA Architecture | I40: Commercial
...

Sheet Copy of Current
A1: ID | B1: Order | C1: Title | D1: ID | E1: Location | F1: Size (Sq. Ft) | G1: Role | H1: Worksheet Role | I1: Designed By | J1: Worksheet Designed By | K1: Architecture by | L1: Worksheet Architecture | M1: Categories | N1: Permalink | O1: Image Featured | P1: Slug
A2: 439 | B2: 1 | C2: Boqueria Restaurant | D2: 439 | E2: Midtown | F2: 10500 | G2: General Contractor | H2: =VLOOKUP(A2, 'Old Worksheet'!B:H,7, false) -> #N/A | I2: Studio Razavi | J2: =VLOOKUP(A2, 'Old Worksheet'!B:I,8,false) -> #N/A | L2: =VLOOKUP(A2, 'Old Worksheet'!B:J,9,false) -> #N/A | M2: Commercial | N2: https://www.streamlineusa.com/commercial/boqueria-restaurant/ | O2: http://www.streamlineusa.com/wp-content/uploads/2019/12/Featured-1-scaled.jpg | P2: boqueria-restaurant
A3: 552 | B3: 1 | C3: Duane Street Penthouse | D3: 552 | E3: Tribeca | F3: 4000 | G3: General Contractor | H3: =VLOOKUP(A3, 'Old Worksheet'!B:H,7, false) -> #N/A | I3: Dean Winters and Diana Gomez | J3: =VLOOKUP(A3, 'Old Worksheet'!B:I,8,false) -> #N/A | K3: SWA Architecture | L3: =VLOOKUP(A3, 'Old Worksheet'!B:J,9,false) -> #N/A | M3: Residential | N3: https://www.streamlineusa.com/residential/duane-street-penthouse/ | O3: http://www.streamlineusa.com/wp-content/uploads/2019/12/20210310_129DuaneSt-3975-2-scaled.jpg | P3: duane-street-penthouse
A4: 436 | B4: 2 | C4: Sugarcane Raw Bar And Grill | D4: 436 | E4: Brooklyn | F4: 12500 | G4: General Contractor + Millwork | H4: =VLOOKUP(A4, 'Old Worksheet'!B:H,7, false) -> #N/A | I4: CetraRuddy Design | J4: =VLOOKUP(A4, 'Old Worksheet'!B:I,8,false) -> #N/A | K4: Lawrence Jones Architecture | L4: =VLOOKUP(A4, 'Old Worksheet'!B:J,9,false) -> #N/A | M4: Commercial | N4: https://www.streamlineusa.com/commercial/sugar-cane-raw-bar-and-grill/ | O4: http://www.streamlineusa.com/wp-content/uploads/2019/12/Sugarcane-Featured.jpg | P4: sugar-cane-raw-bar-and-grill
A5: 2306 | B5: 2 | C5: e64th St Townhouse | D5: 2306 | E5: Lenox Hill | F5: 3800 | G5: General Contractor | H5: =VLOOKUP(A5, 'Old Worksheet'!B:H,7, false) -> #N/A | I5: Virginia Tupker Interiors | J5: =VLOOKUP(A5, 'Old Worksheet'!B:I,8,false) -> #N/A | K5: MZA Architecture | L5: =VLOOKUP(A5, 'Old Worksheet'!B:J,9,false) -> #N/A | M5: Residential | N5: https://www.streamlineusa.com/residential/e64-st-townhouse/ | O5: http://www.streamlineusa.com/wp-content/uploads/2020/05/20200416_118East64th-3022.jpg | P5: e64-st-townhouse
A6: 433 | B6: 3 | C6: Grand Ole Opry City Stage | D6: 433 | E6: Times Square | F6: 22000 | G6: Construction Manager | H6: =VLOOKUP(A6, 'Old Worksheet'!B:H,7, false) -> #N/A | I6: SWA Architecture, Morris Nathanson Interior Design | J6: =VLOOKUP(A6, 'Old Worksheet'!B:I,8,false) -> #N/A | L6: =VLOOKUP(A6, 'Old Worksheet'!B:J,9,false) -> #N/A | M6: Commercial | N6: https://www.streamlineusa.com/commercial/grand-ole-opry-city-stage/ | O6: http://www.streamlineusa.com/wp-content/uploads/2019/12/OPRY1.jpg | P6: grand-ole-opry-city-stage
A7: 570 | B7: 3 | C7: 69th St Townhouse | D7: 570 | E7: Upper West Side | F7: 6000 | G7: General Contractor + Millwork | H7: =VLOOKUP(A7, 'Old Worksheet'!B:H,7, false) -> #N/A | I7: Fury Design | J7: =VLOOKUP(A7, 'Old Worksheet'!B:I,8,false) -> #N/A | L7: =VLOOKUP(A7, 'Old Worksheet'!B:J,9,false) -> #N/A | M7: Residential | N7: https://www.streamlineusa.com/residential/69th-st-townhouse/ | O7: http://www.streamlineusa.com/wp-content/uploads/2019/12/BlackHenselNYC_021-scaled.jpg | P7: 69th-st-townhouse
A8: 506 | B8: 4 | C8: Spring Studios, Spring Place | D8: 506 | E8: Tribeca | F8: 15000 | G8: General Contractor | H8: =VLOOKUP(A8, 'Old Worksheet'!B:H,7, false) -> #N/A | I8: Bluarch Architecture and Design | J8: =VLOOKUP(A8, 'Old Worksheet'!B:I,8,false) -> #N/A | L8: =VLOOKUP(A8, 'Old Worksheet'!B:J,9,false) -> #N/A | M8: Commercial | N8: https://www.streamlineusa.com/commercial/spring-studios-spring-place/ | O8: http://www.streamlineusa.com/wp-content/uploads/2019/12/SP2020_3.png | P8: spring-studios-spring-place
A9: 531 | B9: 4 | C9: St. Lukes Place townhouse | D9: 531 | E9: West Village | F9: 5500 | G9: General Contractor | H9: =VLOOKUP(A9, 'Old Worksheet'!B:H,7, false) -> General Contractor | I9: Barlis Wedlick | J9: =VLOOKUP(A9, 'Old Worksheet'!B:I,8,false) -> Barlis Wedlick | K9: Barlis Wedlick | L9: =VLOOKUP(A9, 'Old Worksheet'!B:J,9,false) -> Barlis Wedlick | M9: Residential | N9: https://www.streamlineusa.com/residential/st-lukes-place-townhouse/ | O9: http://www.streamlineusa.com/wp-content/uploads/2019/12/1-1.jpg | P9: st-lukes-place-townhouse
A10: 517 | B10: 5 | C10: Hudson Street Penthouse | D10: 517 | E10: Tribeca | F10: 3500 | G10: Millwork + Finishes | H10: =VLOOKUP(A10, 'Old Worksheet'!B:H,7, false) -> #N/A | I10: Alex may | J10: =VLOOKUP(A10, 'Old Worksheet'!B:I,8,false) -> #N/A | L10: =VLOOKUP(A10, 'Old Worksheet'!B:J,9,false) -> #N/A | M10: Residential | N10: https://www.streamlineusa.com/residential/hudson-street-penthouse/ | O10: http://www.streamlineusa.com/wp-content/uploads/2019/12/Hudson-Featured-1.jpg | P10: hudson-street-penthouse
A11: 555 | B11: 5 | C11: Indeed Corporate Office Suite | D11: 555 | E11: Midtown | F11: 36000 | G11: Carpentry + Millwork | H11: =VLOOKUP(A11, 'Old Worksheet'!B:H,7, false) -> #N/A | I11: Indeed corporate | J11: =VLOOKUP(A11, 'Old Worksheet'!B:I,8,false) -> #N/A | L11: =VLOOKUP(A11, 'Old Worksheet'!B:J,9,false) -> #N/A | M11: Commercial | N11: https://www.streamlineusa.com/commercial/indeed-corporate-office-suite/ | O11: http://www.streamlineusa.com/wp-content/uploads/2019/12/Indeed-Updated-Featured.jpg | P11: indeed-corporate-office-suite
A12: 561 | B12: 6 | C12: KITH | D12: 561 | E12: NoHo | F12: 7500 | G12: General Contractor | H12: =VLOOKUP(A12, 'Old Worksheet'!B:H,7, false) -> #N/A | I12: Snarkitecture | J12: =VLOOKUP(A12, 'Old Worksheet'!B:I,8,false) -> #N/A | L12: =VLOOKUP(A12, 'Old Worksheet'!B:J,9,false) -> #N/A | M12: Commercial | N12: https://www.streamlineusa.com/commercial/kith/ | O12: http://www.streamlineusa.com/wp-content/uploads/2019/12/StreamlineUSA-RET-Kith-03-4.37x3.4.jpg | P12: kith
A13: 2842 | B13: 6 | C13: Riverside Drive Apartment | D13: 2842 | E13: Morningside Heights | F13: 2900 | G13: General Contractor | H13: =VLOOKUP(A13, 'Old Worksheet'!B:H,7, false) -> #N/A | I13: Samantha Orley Interiors | J13: =VLOOKUP(A13, 'Old Worksheet'!B:I,8,false) -> #N/A | K13: MZA Architecture | L13: =VLOOKUP(A13, 'Old Worksheet'!B:J,9,false) -> #N/A | M13: Residential | N13: https://www.streamlineusa.com/residential/riverside-drive-apartment/ | O13: http://www.streamlineusa.com/wp-content/uploads/2022/02/420-riverside-134.jpg | P13: riverside-drive-apartment
A14: 546 | B14: 7 | C14: Versa at the Marriott Renaissance | D14: 546 | E14: Herald Square | F14: 18000 | G14: Construction Manager | H14: =VLOOKUP(A14, 'Old Worksheet'!B:H,7, false) -> #N/A | I14: Celano Design | J14: =VLOOKUP(A14, 'Old Worksheet'!B:I,8,false) -> #N/A | L14: =VLOOKUP(A14, 'Old Worksheet'!B:J,9,false) -> #N/A | M14: Commercial | N14: https://www.streamlineusa.com/commercial/versa-marriott/ | O14: http://www.streamlineusa.com/wp-content/uploads/2019/12/Versa-3.jpg | P14: versa-marriott
A15: 2847 | B15: 7 | C15: WARREN ST APT | D15: 2847 | E15: Tribeca | F15: 2600 | G15: General Contractor | H15: =VLOOKUP(A15, 'Old Worksheet'!B:H,7, false) -> #N/A | I15: Current Interiors | J15: =VLOOKUP(A15, 'Old Worksheet'!B:I,8,false) -> #N/A | K15: Michael Tower Architecture | L15: =VLOOKUP(A15, 'Old Worksheet'!B:J,9,false) -> #N/A | M15: Residential | N15: https://www.streamlineusa.com/residential/warren-st-apt/ | O15: http://www.streamlineusa.com/wp-content/uploads/2022/02/20210222_30WarrenSt-0178.jpg | P15: warren-st-apt
A16: 491 | B16: 8 | C16: Kat & Theo | D16: 491 | E16: Flatiron District | F16: 2300 | G16: General Contractor + Millwork | H16: =VLOOKUP(A16, 'Old Worksheet'!B:H,7, false) -> #N/A | I16: Aviva Collective | J16: =VLOOKUP(A16, 'Old Worksheet'!B:I,8,false) -> #N/A | L16: =VLOOKUP(A16, 'Old Worksheet'!B:J,9,false) -> #N/A | M16: Commercial | N16: https://www.streamlineusa.com/commercial/kat-theo/ | O16: http://www.streamlineusa.com/wp-content/uploads/2019/12/Screen-Shot-2016-03-02-at-1.48.15-PM.jpg | P16: kat-theo
A17: 2504 | B17: 8 | C17: 12th st townhouse | D17: 2504 | E17: Greenwich Village | F17: 7000 | G17: Carpentry Millwork + Finishes | H17: =VLOOKUP(A17, 'Old Worksheet'!B:H,7, false) -> #N/A | I17: Elisabeth de Kergorlay | J17: =VLOOKUP(A17, 'Old Worksheet'!B:I,8,false) -> #N/A | L17: =VLOOKUP(A17, 'Old Worksheet'!B:J,9,false) -> #N/A | M17: Residential | N17: https://www.streamlineusa.com/residential/12th-st-townhouse-greenwich-village/ | O17: http://www.streamlineusa.com/wp-content/uploads/2020/07/5th-Ave-Featured-copy.jpg | P17: 12th-st-townhouse-greenwich-village
A18: 509 | B18: 9 | C18: Burger & Lobster | D18: 509 | E18: Bryant Park | F18: 8500 | G18: General Contractor + Millwork | H18: =VLOOKUP(A18, 'Old Worksheet'!B:H,7, false) -> #N/A | I18: MZA Architecture | J18: =VLOOKUP(A18, 'Old Worksheet'!B:I,8,false) -> #N/A | L18: =VLOOKUP(A18, 'Old Worksheet'!B:J,9,false) -> #N/A | M18: Commercial | N18: https://www.streamlineusa.com/commercial/burger-lobster/ | O18: http://www.streamlineusa.com/wp-content/uploads/2019/12/BURGERLOBSTER3.jpg | P18: burger-lobster
A19: 567 | B19: 9 | C19: Horatio St. Townhouse | D19: 567 | E19: Meat Packing District | F19: 3200 | G19: General Contractor + Millwork | H19: =VLOOKUP(A19, 'Old Worksheet'!B:H,7, false) -> General Contractor + Millwork | I19: Tersigni Palachek Design | J19: =VLOOKUP(A19, 'Old Worksheet'!B:I,8,false) -> Tersigni Palachek Design | K19: David Bae Architect | L19: =VLOOKUP(A19, 'Old Worksheet'!B:J,9,false) -> David Bae Architect | M19: Residential | N19: https://www.streamlineusa.com/residential/horatio-st-townhouse/ | O19: http://www.streamlineusa.com/wp-content/uploads/2019/12/tersigni-palachek-residential-west-village-02.png | P19: horatio-st-townhouse
A20: 512 | B20: 10 | C20: Momofuku KO | D20: 512 | E20: Bowery | F20: 4500 | G20: General Contractor | H20: =VLOOKUP(A20, 'Old Worksheet'!B:H,7, false) -> #N/A | I20: Richard Lewis Architecture | J20: =VLOOKUP(A20, 'Old Worksheet'!B:I,8,false) -> #N/A | L20: =VLOOKUP(A20, 'Old Worksheet'!B:J,9,false) -> #N/A | M20: Commercial | N20: https://www.streamlineusa.com/commercial/momofuku-ko/ | O20: http://www.streamlineusa.com/wp-content/uploads/2019/12/Momofuku-Featured.jpg | P20: momofuku-ko
A21: 1835 | B21: 10 | C21: Lexington Ave Townhouse | D21: 1835 | E21: Upper East Side | F21: 4500 | G21: General Contractor | H21: =VLOOKUP(A21, 'Old Worksheet'!B:H,7, false) -> #N/A | I21: Salvatore LaRosa | J21: =VLOOKUP(A21, 'Old Worksheet'!B:I,8,false) -> #N/A | K21: B5 Studio Architects | L21: =VLOOKUP(A21, 'Old Worksheet'!B:J,9,false) -> #N/A | M21: Residential | N21: https://www.streamlineusa.com/residential/lexington-ave-townhouse/ | O21: http://www.streamlineusa.com/wp-content/uploads/2020/02/UES-8-e1595540404244.jpg | P21: lexington-ave-townhouse
A22: 537 | B22: 11 | C22: West 23rd St. Townhouse | D22: 537 | E22: Chelsea | F22: 2200 | G22: General Contractor + Millwork | H22: =VLOOKUP(A22, 'Old Worksheet'!B:H,7, false) -> #N/A | I22: Tersigni Palachek Design | J22: =VLOOKUP(A22, 'Old Worksheet'!B:I,8,false) -> #N/A | K22: Tersigni Palachek Design | L22: =VLOOKUP(A22, 'Old Worksheet'!B:J,9,false) -> #N/A | M22: Residential | N22: https://www.streamlineusa.com/residential/west-23rd-townhouse-2/ | O22: http://www.streamlineusa.com/wp-content/uploads/2019/12/W23-Featured.jpg.png | P22: west-23rd-townhouse-2
A23: 549 | B23: 11 | C23: Gunter-Seeger | D23: 549 | E23: West Village | F23: 3300 | G23: General Contractor + Millwork | H23: =VLOOKUP(A23, 'Old Worksheet'!B:H,7, false) -> General Contractor + Millwork | I23: AWI Interiors | J23: =VLOOKUP(A23, 'Old Worksheet'!B:I,8,false) -> AWI Interiors | L23: =VLOOKUP(A23, 'Old Worksheet'!B:J,9,false) | M23: Commercial | N23: https://www.streamlineusa.com/commercial/gunter-seeger/ | O23: http://www.streamlineusa.com/wp-content/uploads/2019/12/Gunter-3.jpg | P23: gunter-seeger
A24: 2850 | B24: 12 | C24: Hudson Yards Mall | D24: 2850 | E24: Hudson Yards | F24: 3500 | G24: General Contractor | H24: =VLOOKUP(A24, 'Old Worksheet'!B:H,7, false) -> #N/A | I24: Robert Jaimeson design | J24: =VLOOKUP(A24, 'Old Worksheet'!B:I,8,false) -> #N/A | L24: =VLOOKUP(A24, 'Old Worksheet'!B:J,9,false) -> #N/A | M24: Commercial | N24: https://www.streamlineusa.com/commercial/hudson-yards-mall/ | O24: http://www.streamlineusa.com/wp-content/uploads/2022/02/20210222_HudsonYardsMall-0087-scaled.jpg | P24: hudson-yards-mall
A25: 2860 | B25: 12 | C25: Wyckoff Townhouse | D25: 2860 | E25: Boerum Hill | F25: 4500 | G25: General Contractor | H25: =VLOOKUP(A25, 'Old Worksheet'!B:H,7, false) -> #N/A | I25: Current Interiors, Rachel Kane, and Xandro Aventajado | J25: =VLOOKUP(A25, 'Old Worksheet'!B:I,8,false) -> #N/A | L25: =VLOOKUP(A25, 'Old Worksheet'!B:J,9,false) -> #N/A | M25: Residential | N25: https://www.streamlineusa.com/residential/wyckoff-townhouse/ | O25: http://www.streamlineusa.com/wp-content/uploads/2022/02/20211202_118WyckoffSt-0964-scaled.jpg | P25: wyckoff-townhouse
A26: 443 | B26: 13 | C26: Mint Kitchen Restaurant | D26: 443 | E26: West Village | F26: 4000 | G26: General Contractor | H26: =VLOOKUP(A26, 'Old Worksheet'!B:H,7, false) -> #N/A | I26: Creme | J26: =VLOOKUP(A26, 'Old Worksheet'!B:I,8,false) -> #N/A | K26: MZA Architecture | L26: =VLOOKUP(A26, 'Old Worksheet'!B:J,9,false) -> #N/A | M26: Commercial | N26: https://www.streamlineusa.com/commercial/mint-kitchen-restaurant/ | O26: http://www.streamlineusa.com/wp-content/uploads/2019/12/Creme_Mint-Kitchen_HR-11-scaled.jpg | P26: mint-kitchen-restaurant
A27: 523 | B27: 13 | C27: Madison Ave Duplex | D27: 523 | E27: Murray Hill | F27: 3400 | G27: General Contractor + Millwork | H27: =VLOOKUP(A27, 'Old Worksheet'!B:H,7, false) -> #N/A | I27: Lynch Eisinger Design | J27: =VLOOKUP(A27, 'Old Worksheet'!B:I,8,false) -> #N/A | L27: =VLOOKUP(A27, 'Old Worksheet'!B:J,9,false) -> #N/A | M27: Residential | N27: https://www.streamlineusa.com/residential/madison-ave-duplex-2/ | O27: http://www.streamlineusa.com/wp-content/uploads/2019/12/SL-_-Residential-_-215-Madision-_-Residence-3.425x3.jpg | P27: madison-ave-duplex-2
A28: 494 | B28: 14 | C28: ViVVI Daycare Tribeca | D28: 494 | E28: Tribeca | F28: 10000 | G28: General Contractor | H28: =VLOOKUP(A28, 'Old Worksheet'!B:H,7, false) -> General Contractor | I28: eleven of eleven architecture | J28: =VLOOKUP(A28, 'Old Worksheet'!B:I,8,false) -> eleven of eleven architecture | L28: =VLOOKUP(A28, 'Old Worksheet'!B:J,9,false) | M28: Commercial | N28: https://www.streamlineusa.com/commercial/vivvi-daycare-tribeca/ | O28: http://www.streamlineusa.com/wp-content/uploads/2019/12/11OF11-VIVVI-F.OUDEMAN11-scaled.jpg | P28: vivvi-daycare-tribeca
A29: 520 | B29: 14 | C29: Tribeca Loft | D29: 520 | E29: Tribeca | F29: 2500 | G29: Millwork + Finishes | H29: =VLOOKUP(A29, 'Old Worksheet'!B:H,7, false) -> #N/A | I29: Bore | J29: =VLOOKUP(A29, 'Old Worksheet'!B:I,8,false) -> #N/A | L29: =VLOOKUP(A29, 'Old Worksheet'!B:J,9,false) -> #N/A | M29: Residential | N29: https://www.streamlineusa.com/residential/tribeca-loft/ | O29: http://www.streamlineusa.com/wp-content/uploads/2019/12/Tribeca-Loft-Featured-scaled.jpg | P29: tribeca-loft
A30: 540 | B30: 15 | C30: e63rd st Penthouse | D30: 540 | E30: Lenox Hill | F30: 1700 | G30: General Contractor + Millwork | H30: =VLOOKUP(A30, 'Old Worksheet'!B:H,7, false) -> #N/A | I30: Jennifer Aderholdt Design | J30: =VLOOKUP(A30, 'Old Worksheet'!B:I,8,false) -> #N/A | K30: SWA Architecture | L30: =VLOOKUP(A30, 'Old Worksheet'!B:J,9,false) -> #N/A | M30: Residential | N30: https://www.streamlineusa.com/residential/e63-st-penthouse/ | O30: http://www.streamlineusa.com/wp-content/uploads/2019/12/Upper-East-Side-Penthouse-Featured.jpg | P30: e63-st-penthouse
A31: 2853 | B31: 15 | C31: Vivvi Daycare Hudson Yards | D31: 2853 | E31: Hudson Yards | F31: 7500 | G31: General Contractor | H31: =VLOOKUP(A31, 'Old Worksheet'!B:H,7, false) -> General Contractor | I31: Eleven of Eleven design | J31: =VLOOKUP(A31, 'Old Worksheet'!B:I,8,false) -> Eleven of Eleven design | K31: Carol Gretter Elven of Eleven architecture | L31: =VLOOKUP(A31, 'Old Worksheet'!B:J,9,false) -> Carol Gretter Elven of Eleven architecture | M31: Commercial | N31: https://www.streamlineusa.com/commercial/vivvi-daycare-hudson-yards/ | O31: http://www.streamlineusa.com/wp-content/uploads/2022/02/20210219_55HudsonYards-5373-scaled.jpg | P31: vivvi-daycare-hudson-yards
A32: 2396 | B32: 16 | C32: 84th st townhouse | D32: 2396 | E32: Jackson Heights | F32: 2200 | G32: General Contractor | H32: =VLOOKUP(A32, 'Old Worksheet'!B:H,7, false) -> #N/A | I32: Nathalie Akiya Design | J32: =VLOOKUP(A32, 'Old Worksheet'!B:I,8,false) -> #N/A | K32: SWA Architecture | L32: =VLOOKUP(A32, 'Old Worksheet'!B:J,9,false) -> #N/A | M32: Residential | N32: https://www.streamlineusa.com/residential/84th-st-townhouse/ | O32: http://www.streamlineusa.com/wp-content/uploads/2020/05/Jackson-Heights-Featured.png | P32: 84th-st-townhouse
A33: 2520 | B33: 16 | C33: Haus Nightclub | D33: 2520 | E33: Lower Manhattan | F33: 5500 | G33: General Contractor | H33: =VLOOKUP(A33, 'Old Worksheet'!B:H,7, false) -> #N/A | I33: John Rawlins Design | J33: =VLOOKUP(A33, 'Old Worksheet'!B:I,8,false) -> #N/A | K33: SWA Architecture | L33: =VLOOKUP(A33, 'Old Worksheet'!B:J,9,false) -> #N/A | M33: Commercial | N33: https://www.streamlineusa.com/commercial/haus-nightclub/ | O33: http://www.streamlineusa.com/wp-content/uploads/2020/07/Haus-Featured.jpg | P33: haus-nightclub
A34: 1907 | B34: 17 | C34: Sullivan St duplex | D34: 1907 | E34: SOHO | F34: 6000 | G34: Millwork + Finishes | H34: =VLOOKUP(A34, 'Old Worksheet'!B:H,7, false) -> #N/A | I34: Butter and Eggs Design | J34: =VLOOKUP(A34, 'Old Worksheet'!B:I,8,false) -> #N/A | K34: Michael Tower Architecture | L34: =VLOOKUP(A34, 'Old Worksheet'!B:J,9,false) -> #N/A | M34: Residential | N34: https://www.streamlineusa.com/residential/sullivan-st-duplex-2/ | O34: http://www.streamlineusa.com/wp-content/uploads/2020/02/DSC_0847-scaled.jpg | P34: sullivan-st-duplex-2
A35: 1931 | B35: 18 | C35: Mackage SoHo | D35: 1931 | E35: SoHo | F35: 4500 | G35: General Contractor | H35: =VLOOKUP(A35, 'Old Worksheet'!B:H,7, false) -> #N/A | I35: Burdifilek | J35: =VLOOKUP(A35, 'Old Worksheet'!B:I,8,false) -> #N/A | L35: =VLOOKUP(A35, 'Old Worksheet'!B:J,9,false) -> #N/A | M35: Commercial | N35: https://www.streamlineusa.com/commercial/mackage-soho/ | O35: http://www.streamlineusa.com/wp-content/uploads/2020/02/IMG_8648-scaled.jpg | P35: mackage-soho
A36: 2409 | B36: 18 | C36: Upper West Side Apartment | D36: 2409 | E36: Upper West Side | F36: 1400 | G36: General Contractor | H36: =VLOOKUP(A36, 'Old Worksheet'!B:H,7, false) -> #N/A | I36: Yael and Ori Morag | J36: =VLOOKUP(A36, 'Old Worksheet'!B:I,8,false) -> #N/A | K36: MZA Architecture | L36: =VLOOKUP(A36, 'Old Worksheet'!B:J,9,false) -> #N/A | M36: Residential | N36: https://www.streamlineusa.com/residential/upper-west-side-apartment/ | O36: http://www.streamlineusa.com/wp-content/uploads/2020/05/Upper-West-Side-Apt-Featured.jpg | P36: upper-west-side-apartment
A37: 2425 | B37: 19 | C37: My Darling Ivy | D37: 2425 | E37: Chelsea | F37: 1500 | G37: General Contractor | H37: =VLOOKUP(A37, 'Old Worksheet'!B:H,7, false) -> #N/A | I37: VJ Moscaritola | J37: =VLOOKUP(A37, 'Old Worksheet'!B:I,8,false) -> #N/A | K37: Studio Stigsby | L37: =VLOOKUP(A37, 'Old Worksheet'!B:J,9,false) -> #N/A | M37: Commercial | N37: https://www.streamlineusa.com/commercial/my-darling-ivy/ | O37: http://www.streamlineusa.com/wp-content/uploads/2020/05/My-Darling-Ivy-Featured.jpg | P37: my-darling-ivy
A38: 2838 | B38: 19 | C38: 53rd st studio | D38: 2838 | E38: Hell's Kitchen | F38: 750 | G38: General Contractor | H38: =VLOOKUP(A38, 'Old Worksheet'!B:H,7, false) -> #N/A | I38: LDN interiors | J38: =VLOOKUP(A38, 'Old Worksheet'!B:I,8,false) -> #N/A | L38: =VLOOKUP(A38, 'Old Worksheet'!B:J,9,false) -> #N/A | M38: Residential | N38: https://www.streamlineusa.com/residential/53rd-st-studio/ | O38: http://www.streamlineusa.com/wp-content/uploads/2022/02/20210310_425West53rdSt-3669.jpg | P38: 53rd-st-studio
A39: 534 | B39: 20 | C39: Thompson St. Studio | D39: 534 | E39: SOHO | F39: 600 | G39: General Contractor + Millwork | H39: =VLOOKUP(A39, 'Old Worksheet'!B:H,7, false) -> #N/A | I39: SWA Architecture | J39: =VLOOKUP(A39, 'Old Worksheet'!B:I,8,false) -> #N/A | L39: =VLOOKUP(A39, 'Old Worksheet'!B:J,9,false) -> #N/A | M39: Residential | N39: https://www.streamlineusa.com/residential/thompson-st-studio/ | O39: http://www.streamlineusa.com/wp-content/uploads/2019/12/THOMPSON_STUDIO-Featured-scaled.jpg | P39: thompson-st-studio
A40: 564 | B40: 20 | C40: Washington Sq. Dermatology | D40: 564 | E40: West Village | F40: 2500 | G40: General Contractor | H40: =VLOOKUP(A40, 'Old Worksheet'!B:H,7, false) -> #N/A | I40: Dr. Samer Jaber | J40: =VLOOKUP(A40, 'Old Worksheet'!B:I,8,false) -> #N/A | L40: =VLOOKUP(A40, 'Old Worksheet'!B:J,9,false) -> #N/A | M40: Commercial | N40: https://www.streamlineusa.com/commercial/upper-east-side-townhouse/ | O40: http://www.streamlineusa.com/wp-content/uploads/2019/12/wash.jpg | P40: upper-east-side-townhouse
...

Sheet Upload
A1: ID | B1: Order | C1: Title | D1: Location | E1: Size (Sq. Ft) | F1: Role | G1: Designed By | H1: Architecture by | I1: Categories | J1: Permalink | K1: Image Featured | L1: Slug
A2: 433 | B2: 3 | C2: Grand Ole Opry City Stage | D2: Times Square | E2: 22000 | F2: Construction Manager | G2: SWA Architecture, Morris Nathanson Interior Design | I2: Commercial | J2: https://www.streamlineusa.com/commercial/grand-ole-opry-city-stage/ | K2: http://www.streamlineusa.com/wp-content/uploads/2019/12/OPRY1.jpg | L2: grand-ole-opry-city-stage
A3: 436 | B3: 2 | C3: Sugarcane Raw Bar And Grill | D3: Brooklyn | E3: 12500 | F3: General Contractor + Millwork | G3: CetraRuddy Design | H3: Lawrence Jones Architecture | I3: Commercial | J3: https://www.streamlineusa.com/commercial/sugar-cane-raw-bar-and-grill/ | K3: http://www.streamlineusa.com/wp-content/uploads/2019/12/Sugarcane-Featured.jpg | L3: sugar-cane-raw-bar-and-grill
A4: 439 | B4: 1 | C4: Boqueria Restaurant | D4: Midtown | E4: 10500 | F4: General Contractor | G4: Studio Razavi | I4: Commercial | J4: https://www.streamlineusa.com/commercial/boqueria-restaurant/ | K4: http://www.streamlineusa.com/wp-content/uploads/2019/12/Featured-1-scaled.jpg | L4: boqueria-restaurant
A5: 443 | B5: 13 | C5: Mint Kitchen Restaurant | D5: West Village | E5: 4000 | F5: General Contractor | G5: Creme | H5: MZA Architecture | I5: Commercial | J5: https://www.streamlineusa.com/commercial/mint-kitchen-restaurant/ | K5: http://www.streamlineusa.com/wp-content/uploads/2019/12/Creme_Mint-Kitchen_HR-11-scaled.jpg | L5: mint-kitchen-restaurant
A6: 491 | B6: 8 | C6: Kat & Theo | D6: Flatiron District | E6: 2300 | F6: General Contractor + Millwork | G6: Aviva Collective | I6: Commercial | J6: https://www.streamlineusa.com/commercial/kat-theo/ | K6: http://www.streamlineusa.com/wp-content/uploads/2019/12/Screen-Shot-2016-03-02-at-1.48.15-PM.jpg | L6: kat-theo
A7: 494 | B7: 14 | C7: ViVVI Daycare Tribeca | D7: Tribeca | E7: 10000 | F7: General Contractor | G7: eleven of eleven architecture | I7: Commercial | J7: https://www.streamlineusa.com/commercial/vivvi-daycare-tribeca/ | K7: http://www.streamlineusa.com/wp-content/uploads/2019/12/11OF11-VIVVI-F.OUDEMAN11-scaled.jpg | L7: vivvi-daycare-tribeca
A8: 503 | B8: 21 | C8: Free People Retail Store | D8: Meatpacking District | E8: 7000 | F8: Carpentry + Finishes | G8: David Levy Architecture | I8: Commercial | J8: https://www.streamlineusa.com/commercial/free-people-retail-store/ | K8: http://www.streamlineusa.com/wp-content/uploads/2019/12/Free-People-Updated-Featured.jpg | L8: free-people-retail-store
A9: 506 | B9: 4 | C9: Spring Studios, Spring Place | D9: Tribeca | E9: 15000 | F9: General Contractor | G9: Bluarch Architecture and Design | I9: Commercial | J9: https://www.streamlineusa.com/commercial/spring-studios-spring-place/ | K9: http://www.streamlineusa.com/wp-content/uploads/2019/12/SP2020_3.png | L9: spring-studios-spring-place
A10: 509 | B10: 9 | C10: Burger & Lobster | D10: Bryant Park | E10: 8500 | F10: General Contractor + Millwork | G10: MZA Architecture | I10: Commercial | J10: https://www.streamlineusa.com/commercial/burger-lobster/ | K10: http://www.streamlineusa.com/wp-content/uploads/2019/12/BURGERLOBSTER3.jpg | L10: burger-lobster
A11: 512 | B11: 10 | C11: Momofuku KO | D11: Bowery | E11: 4500 | F11: General Contractor | G11: Richard Lewis Architecture | I11: Commercial | J11: https://www.streamlineusa.com/commercial/momofuku-ko/ | K11: http://www.streamlineusa.com/wp-content/uploads/2019/12/Momofuku-Featured.jpg | L11: momofuku-ko
A12: 517 | B12: 5 | C12: Hudson Street Penthouse | D12: Tribeca | E12: 3500 | F12: Millwork + Finishes | G12: Alex may | I12: Residential | J12: https://www.streamlineusa.com/residential/hudson-street-penthouse/ | K12: http://www.streamlineusa.com/wp-content/uploads/2019/12/Hudson-Featured-1.jpg | L12: hudson-street-penthouse
A13: 520 | B13: 14 | C13: Tribeca Loft | D13: Tribeca | E13: 2500 | F13: Millwork + Finishes | G13: Bore | I13: Residential | J13: https://www.streamlineusa.com/residential/tribeca-loft/ | K13: http://www.streamlineusa.com/wp-content/uploads/2019/12/Tribeca-Loft-Featured-scaled.jpg | L13: tribeca-loft
A14: 523 | B14: 13 | C14: Madison Ave Duplex | D14: Murray Hill | E14: 3400 | F14: General Contractor + Millwork | G14: Lynch Eisinger Design | I14: Residential | J14: https://www.streamlineusa.com/residential/madison-ave-duplex-2/ | K14: http://www.streamlineusa.com/wp-content/uploads/2019/12/SL-_-Residential-_-215-Madision-_-Residence-3.425x3.jpg | L14: madison-ave-duplex-2
A15: 527 | B15: 21 | C15: 1st Ave Apartment | D15: Murray Hill | E15: 2000 | F15: General Contractor + Millwork | G15: SWA Architecture | H15: SWA Architecture | I15: Residential | J15: https://www.streamlineusa.com/residential/1st-ave-apt/ | K15: http://www.streamlineusa.com/wp-content/uploads/2019/12/Murray-Hill-Featured.jpg | L15: 1st-ave-apt
A16: 531 | B16: 4 | C16: St. Lukes Place townhouse | D16: West Village | E16: 5500 | F16: General Contractor | G16: Barlis Wedlick | H16: Barlis Wedlick | I16: Residential | J16: https://www.streamlineusa.com/residential/st-lukes-place-townhouse/ | K16: http://www.streamlineusa.com/wp-content/uploads/2019/12/1-1.jpg | L16: st-lukes-place-townhouse
A17: 534 | B17: 20 | C17: Thompson St. Studio | D17: SOHO | E17: 600 | F17: General Contractor + Millwork | G17: SWA Architecture | I17: Residential | J17: https://www.streamlineusa.com/residential/thompson-st-studio/ | K17: http://www.streamlineusa.com/wp-content/uploads/2019/12/THOMPSON_STUDIO-Featured-scaled.jpg | L17: thompson-st-studio
A18: 537 | B18: 11 | C18: West 23rd St. Townhouse | D18: Chelsea | E18: 2200 | F18: General Contractor + Millwork | G18: Tersigni Palachek Design | H18: Tersigni Palachek Design | I18: Residential | J18: https://www.streamlineusa.com/residential/west-23rd-townhouse-2/ | K18: http://www.streamlineusa.com/wp-content/uploads/2019/12/W23-Featured.jpg.png | L18: west-23rd-townhouse-2
A19: 540 | B19: 15 | C19: e63rd st Penthouse | D19: Lenox Hill | E19: 1700 | F19: General Contractor + Millwork | G19: Jennifer Aderholdt Design | H19: SWA Architecture | I19: Residential | J19: https://www.streamlineusa.com/residential/e63-st-penthouse/ | K19: http://www.streamlineusa.com/wp-content/uploads/2019/12/Upper-East-Side-Penthouse-Featured.jpg | L19: e63-st-penthouse
A20: 546 | B20: 7 | C20: Versa at the Marriott Renaissance | D20: Herald Square | E20: 18000 | F20: Construction Manager | G20: Celano Design | I20: Commercial | J20: https://www.streamlineusa.com/commercial/versa-marriott/ | K20: http://www.streamlineusa.com/wp-content/uploads/2019/12/Versa-3.jpg | L20: versa-marriott
A21: 549 | B21: 11 | C21: Gunter-Seeger | D21: West Village | E21: 3300 | F21: General Contractor + Millwork | G21: AWI Interiors | I21: Commercial | J21: https://www.streamlineusa.com/commercial/gunter-seeger/ | K21: http://www.streamlineusa.com/wp-content/uploads/2019/12/Gunter-3.jpg | L21: gunter-seeger
A22: 552 | B22: 1 | C22: Duane Street Penthouse | D22: Tribeca | E22: 4000 | F22: General Contractor | G22: Dean Winters and Diana Gomez | H22: SWA Architecture | I22: Residential | J22: https://www.streamlineusa.com/residential/duane-street-penthouse/ | K22: http://www.streamlineusa.com/wp-content/uploads/2019/12/20210310_129DuaneSt-3975-2-scaled.jpg | L22: duane-street-penthouse
A23: 555 | B23: 5 | C23: Indeed Corporate Office Suite | D23: Midtown | E23: 36000 | F23: Carpentry + Millwork | G23: Indeed corporate | I23: Commercial | J23: https://www.streamlineusa.com/commercial/indeed-corporate-office-suite/ | K23: http://www.streamlineusa.com/wp-content/uploads/2019/12/Indeed-Updated-Featured.jpg | L23: indeed-corporate-office-suite
A24: 558 | B24: 24 | C24: Atrium Corporate Office | D24: NoHo | E24: 5000 | F24: General Contractor + Millwork | G24: Sam Ben avraham | H24: Bang 3 Design | I24: Commercial | J24: https://www.streamlineusa.com/commercial/autrium-corporate-office/ | K24: http://www.streamlineusa.com/wp-content/uploads/2019/12/Streamline-USA-Atrium-5.65x4.11.jpg | L24: autrium-corporate-office
A25: 561 | B25: 6 | C25: KITH | D25: NoHo | E25: 7500 | F25: General Contractor | G25: Snarkitecture | I25: Commercial | J25: https://www.streamlineusa.com/commercial/kith/ | K25: http://www.streamlineusa.com/wp-content/uploads/2019/12/StreamlineUSA-RET-Kith-03-4.37x3.4.jpg | L25: kith
A26: 564 | B26: 20 | C26: Washington Sq. Dermatology | D26: West Village | E26: 2500 | F26: General Contractor | G26: Dr. Samer Jaber | I26: Commercial | J26: https://www.streamlineusa.com/commercial/upper-east-side-townhouse/ | K26: http://www.streamlineusa.com/wp-content/uploads/2019/12/wash.jpg | L26: upper-east-side-townhouse
A27: 567 | B27: 9 | C27: Horatio St. Townhouse | D27: Meat Packing District | E27: 3200 | F27: General Contractor + Millwork | G27: Tersigni Palachek Design | H27: David Bae Architect | I27: Residential | J27: https://www.streamlineusa.com/residential/horatio-st-townhouse/ | K27: http://www.streamlineusa.com/wp-content/uploads/2019/12/tersigni-palachek-residential-west-village-02.png | L27: horatio-st-townhouse
A28: 570 | B28: 3 | C28: 69th St Townhouse | D28: Upper West Side | E28: 6000 | F28: General Contractor + Millwork | G28: Fury Design | I28: Residential | J28: https://www.streamlineusa.com/residential/69th-st-townhouse/ | K28: http://www.streamlineusa.com/wp-content/uploads/2019/12/BlackHenselNYC_021-scaled.jpg | L28: 69th-st-townhouse
A29: 1835 | B29: 10 | C29: Lexington Ave Townhouse | D29: Upper East Side | E29: 4500 | F29: General Contractor | G29: Salvatore LaRosa | H29: B5 Studio Architects | I29: Residential | J29: https://www.streamlineusa.com/residential/lexington-ave-townhouse/ | K29: http://www.streamlineusa.com/wp-content/uploads/2020/02/UES-8-e1595540404244.jpg | L29: lexington-ave-townhouse
A30: 1907 | B30: 17 | C30: Sullivan St duplex | D30: SOHO | E30: 6000 | F30: Millwork + Finishes | G30: Butter and Eggs Design | H30: Michael Tower Architecture | I30: Residential | J30: https://www.streamlineusa.com/residential/sullivan-st-duplex-2/ | K30: http://www.streamlineusa.com/wp-content/uploads/2020/02/DSC_0847-scaled.jpg | L30: sullivan-st-duplex-2
A31: 1931 | B31: 18 | C31: Mackage SoHo | D31: SoHo | E31: 4500 | F31: General Contractor | G31: Burdifilek | I31: Commercial | J31: https://www.streamlineusa.com/commercial/mackage-soho/ | K31: http://www.streamlineusa.com/wp-content/uploads/2020/02/IMG_8648-scaled.jpg | L31: mackage-soho
A32: 2306 | B32: 2 | C32: e64th St Townhouse | D32: Lenox Hill | E32: 3800 | F32: General Contractor | G32: Virginia Tupker Interiors | H32: MZA Architecture | I32: Residential | J32: https://www.streamlineusa.com/residential/e64-st-townhouse/ | K32: http://www.streamlineusa.com/wp-content/uploads/2020/05/20200416_118East64th-3022.jpg | L32: e64-st-townhouse
A33: 2345 | B33: 22 | C33: Motel 23 Lounge | D33: Chelsea | E33: 3500 | F33: General Contractor | G33: Colin Fuda | H33: Atelier New York | I33: Commercial | J33: https://www.streamlineusa.com/commercial/motel-23-lounge/ | K33: http://www.streamlineusa.com/wp-content/uploads/2020/05/Motel-23-Featured.jpg | L33: motel-23-lounge
A34: 2366 | B34: 22 | C34: Wainscott, East Hampton Residence | D34: Wainscott, East Hampton | E34: 3200 | F34: Construction Consultant | G34: Nathalie Akiya Design | I34: Residential | J34: https://www.streamlineusa.com/residential/wainscott-east-hampton-residence/ | K34: http://www.streamlineusa.com/wp-content/uploads/2020/05/IMG_1256.png | L34: wainscott-east-hampton-residence
A35: 2384 | B35: 23 | C35: Ground Central Coffee Company | D35: Murray Hill | E35: 550 | F35: General Contractor | G35: Daniel O'Connor Architects | H35: Daniel O'Connor Architects | I35: Commercial | J35: https://www.streamlineusa.com/commercial/ground-central-coffee-company/ | K35: http://www.streamlineusa.com/wp-content/uploads/2020/05/Ground-Central-Featured.jpg | L35: ground-central-coffee-company
A36: 2396 | B36: 16 | C36: 84th st townhouse | D36: Jackson Heights | E36: 2200 | F36: General Contractor | G36: Nathalie Akiya Design | H36: SWA Architecture | I36: Residential | J36: https://www.streamlineusa.com/residential/84th-st-townhouse/ | K36: http://www.streamlineusa.com/wp-content/uploads/2020/05/Jackson-Heights-Featured.png | L36: 84th-st-townhouse
A37: 2409 | B37: 18 | C37: Upper West Side Apartment | D37: Upper West Side | E37: 1400 | F37: General Contractor | G37: Yael and Ori Morag | H37: MZA Architecture | I37: Residential | J37: https://www.streamlineusa.com/residential/upper-west-side-apartment/ | K37: http://www.streamlineusa.com/wp-content/uploads/2020/05/Upper-West-Side-Apt-Featured.jpg | L37: upper-west-side-apartment
A38: 2425 | B38: 19 | C38: My Darling Ivy | D38: Chelsea | E38: 1500 | F38: General Contractor | G38: VJ Moscaritola | H38: Studio Stigsby | I38: Commercial | J38: https://www.streamlineusa.com/commercial/my-darling-ivy/ | K38: http://www.streamlineusa.com/wp-content/uploads/2020/05/My-Darling-Ivy-Featured.jpg | L38: my-darling-ivy
A39: 2504 | B39: 8 | C39: 12th st townhouse | D39: Greenwich Village | E39: 7000 | F39: Carpentry Millwork + Finishes | G39: Elisabeth de Kergorlay | I39: Residential | J39: https://www.streamlineusa.com/residential/12th-st-townhouse-greenwich-village/ | K39: http://www.streamlineusa.com/wp-content/uploads/2020/07/5th-Ave-Featured-copy.jpg | L39: 12th-st-townhouse-greenwich-village
A40: 2520 | B40: 16 | C40: Haus Nightclub | D40: Lower Manhattan | E40: 5500 | F40: General Contractor | G40: John Rawlins Design | H40: SWA Architecture | I40: Commercial | J40: https://www.streamlineusa.com/commercial/haus-nightclub/ | K40: http://www.streamlineusa.com/wp-content/uploads/2020/07/Haus-Featured.jpg | L40: haus-nightclub
...

Sheet Old Worksheet
A1: id | B1: Correct ID | C1: Order of apperance | D1: Title | E1: Project Gallery | F1: Location | G1: Size (Sq. Ft) | H1: Role | I1: Designed By | J1: Architecture by | K1: Categories | L1: Permalink | M1: Image Featured
A2: 2425 | B2: =VLOOKUP(D2, Current!C:C, 2, false) -> #REF! | C2: 8 | D2: 12th st townhouse | E2: http://www.staging3.streamlineusa.com/wp-content/uploads/2020/07/5th-Ave-9496-copy.jpg|http://www.staging3.streamlineusa.com/wp-content/uploads/2020/07/5th-Ave-9495-copy.jpg|http://www.staging3.streamlineusa.com/wp-content/uploads/2020/07/5th-Ave-9494-copy.jpg|http://www.staging3.streamlineusa.com/wp-content/uploads/2020/07/5th-Ave-9493-copy.jpg|http://www.staging3.streamlineusa.com/wp-content/uploads/2020/07/5th-Ave-9492-copy.jpg|http://www.staging3.streamlineusa.com/wp-content/uploads/2020/07/5th-Ave-9491-copy.jpg|http://www.staging3.streamlineusa.com/wp-content/uploads/2020/07/5th-Ave-9490-copy.jpg|http://www.staging3.streamlineusa.com/wp-content/uploads/2020/07/5th-Ave-9488-copy.jpg|http://www.staging3.streamlineusa.com/wp-content/uploads/2020/07/5th-Ave-9485-copy.jpg|http://www.staging3.streamlineusa.com/wp-content/uploads/2020/07/5th-Ave-9483-copy.jpg|http://www.staging3.streamlineusa.com/wp-content/uploads/2020/07/5th-Ave-9481-copy.jpg|http://www.staging3.streamlineusa.com/wp-content/uploads/2020/07/5th-Ave-Featured-copy.jpg | F2: Greenwich Village | G2: 7000 | H2: Carpentry Millwork + Finishes | I2: Elisabeth de Kergorlay | K2: Residential | L2: https://www.staging8.streamlineusa.com/residential/5th-avenue-townhouse/ | M2: https://www.staging8.streamlineusa.com/wp-content/uploads/2020/07/5th-Ave-Featured-copy.jpg
A3: 558 | B3: =VLOOKUP(D3, Current!C:C, 2, false) -> #REF! | C3: 21 | D3: 1st ave apartment | E3: http://www.staging3.streamlineusa.com/wp-content/uploads/2019/12/Murray-Hill-Featured.jpg|http://www.staging3.streamlineusa.com/wp-content/uploads/2019/12/MURRAYHILL1.jpg|http://www.staging3.streamlineusa.com/wp-content/uploads/2019/12/MURRAYHILL2.jpg|http://www.staging3.streamlineusa.com/wp-content/uploads/2019/12/MURRAYHILL4.jpg|http://www.staging3.streamlineusa.com/wp-content/uploads/2019/12/MURRAYHILL3.jpg|http://www.staging3.streamlineusa.com/wp-content/uploads/2019/12/MURRAYHILL5.jpg|http://www.staging3.streamlineusa.com/wp-content/uploads/2019/12/MURRAYHILL7.jpg | F3: Murray Hill | G3: 2000 | H3: General Contractor + Millwork | I3: SWA Architecture | K3: Residential | L3: https://www.staging8.streamlineusa.com/residential/murray-hill-apartments/ | M3: https://www.staging8.streamlineusa.com/wp-content/uploads/2019/12/Murray-Hill-Featured.jpg
A4: 527 | B4: =VLOOKUP(D4, Current!C:C, 2, false) -> #REF! | C4: 19 | D4: 53rd st studio | E4: http://www.staging3.streamlineusa.com/wp-content/uploads/2022/02/20210310_425West53rdSt-3619.jpg|http://www.staging3.streamlineusa.com/wp-content/uploads/2022/02/20210310_425West53rdSt-3624.jpg|http://www.staging3.streamlineusa.com/wp-content/uploads/2022/02/20210310_425West53rdSt-3629.jpg|http://www.staging3.streamlineusa.com/wp-content/uploads/2022/02/20210310_425West53rdSt-3634.jpg|http://www.staging3.streamlineusa.com/wp-content/uploads/2022/02/20210310_425West53rdSt-3639.jpg|http://www.staging3.streamlineusa.com/wp-content/uploads/2022/02/20210310_425West53rdSt-3659.jpg|http://www.staging3.streamlineusa.com/wp-content/uploads/2022/02/20210310_425West53rdSt-3664.jpg|http://www.staging3.streamlineusa.com/wp-content/uploads/2022/02/20210310_425West53rdSt-3669.jpg|http://www.staging3.streamlineusa.com/wp-content/uploads/2022/02/20210310_425West53rdSt-3674.jpg|http://www.staging3.streamlineusa.com/wp-content/uploads/2022/02/20210310_425West53rdSt-3679.jpg|http://www.staging3.streamlineusa.com/wp-content/uploads/2022/02/20210310_425West53rdSt-3684.jpg|http://www.staging3.streamlineusa.com/wp-content/uploads/2022/02/20210310_425West53rdSt-3699.jpg|http://www.staging3.streamlineusa.com/wp-content/uploads/2022/02/20210310_425West53rdSt-3704.jpg|http://www.staging3.streamlineusa.com/wp-content/uploads/2022/02/20210310_425West53rdSt-3709.jpg|http://www.staging3.streamlineusa.com/wp-content/uploads/2022/02/20210310_425West53rdSt-3719.jpg|http://www.staging3.streamlineusa.com/wp-content/uploads/2022/02/20210310_425West53rdSt-3724.jpg|http://www.staging3.streamlineusa.com/wp-content/uploads/2022/02/20210310_425West53rdSt-3739.jpg|http://www.staging3.streamlineusa.com/wp-content/uploads/2022/02/20210310_425West53rdSt-3752.jpg|http://www.staging3.streamlineusa.com/wp-content/uploads/2022/02/20210310_425West53rdSt-3772.jpg|http://www.staging3.streamlineusa.com/wp-content/uploads/2022/02/20210310_425West53rdSt-3776.jpg|http://www.staging3.streamlineusa.com/wp-content/uploads/2022/02/20210310_425West53rdSt-3781.jpg|http://www.staging3.streamlineusa.com/wp-content/uploads/2022/02/20210310_425West53rdSt-3786.jpg|http://www.staging3.streamlineusa.com/wp-content/uploads/2022/02/20210310_425West53rdSt-3791.jpg|http://www.staging3.streamlineusa.com/wp-content/uploads/2019/12/SL-_-Residential-_-215-Madision-_-Residence-3.425x3-1.jpg|http://www.staging3.streamlineusa.com/wp-content/uploads/2019/12/SL-_-Residential-_-215-Madision-_-Residence-3.425x3.jpg | F4: Hell's Kitchen | G4: 750 | H4: General Contractor | I4: LDN interiors | K4: Residential | L4: https://www.staging8.streamlineusa.com/residential/hells-kitchen-apt/ | M4: https://www.staging8.streamlineusa.com/wp-content/uploads/2022/02/20210310_425West53rdSt-3669.jpg
A5: 1835 | B5: =VLOOKUP(D5, Current!C:C, 2, false) -> #REF! | C5: 3 | D5: 69th st townhouse | E5: http://www.staging3.streamlineusa.com/wp-content/uploads/2019/12/BlackHenselNYC_10retouched1-scaled.jpg|http://www.staging3.streamlineusa.com/wp-content/uploads/2019/12/BlackHenselNYC_051-scaled.jpg|http://www.staging3.streamlineusa.com/wp-content/uploads/2019/12/BlackHenselNYC_041-scaled.jpg|http://www.staging3.streamlineusa.com/wp-content/uploads/2019/12/BlackHenselNYC_071-scaled.jpg|http://www.staging3.streamlineusa.com/wp-content/uploads/2019/12/BlackHenselNYC_021-scaled.jpg|http://www.staging3.streamlineusa.com/wp-content/uploads/2019/12/BlackHenselNYC_091-scaled.jpg|http://www.staging3.streamlineusa.com/wp-content/uploads/2019/12/BlackHenselNYC_031-scaled.jpg|http://www.staging3.streamlineusa.com/wp-content/uploads/2019/12/BlackHenselNYC_081-scaled.jpg|http://www.staging3.streamlineusa.com/wp-content/uploads/2019/12/BlackHenselNYC_061-scaled.jpg|http://www.staging3.streamlineusa.com/wp-content/uploads/2019/12/BlackHenselNYC_11retouched1-scaled.jpg|http://www.staging3.streamlineusa.com/wp-content/uploads/2019/12/BlackHenselNYC_011-scaled.jpg|http://www.staging3.streamlineusa.com/wp-content/uploads/2019/12/UWS_TOWNHOUSE4.jpg|http://www.staging3.streamlineusa.com/wp-content/uploads/2019/12/UWS_TOWNHOUSE6.jpg|http://www.staging3.streamlineusa.com/wp-content/uploads/2019/12/UWS_TOWNHOUSE1.jpg|http://www.staging3.streamlineusa.com/wp-content/uploads/2019/12/UWS_TOWNHOUSE7-1.jpg | F5: Upper West Side | G5: 6000 | H5: General Contractor + Millwork | I5: Fury Design | K5: Residential | L5: https://www.staging8.streamlineusa.com/residential/upper-west-side-townhouse/ | M5: https://www.staging8.streamlineusa.com/wp-content/uploads/2019/12/BlackHenselNYC_021-scaled.jpg
A6: 2409 | B6: =VLOOKUP(D6, Current!C:C, 2, false) -> #REF! | C6: 16 | D6: 84th st Townhouse | E6: http://www.staging3.streamlineusa.com/wp-content/uploads/2020/05/Jackson-Heights-Featured.png|http://www.staging3.streamlineusa.com/wp-content/uploads/2020/05/IMG_0457.png|http://www.staging3.streamlineusa.com/wp-content/uploads/2020/05/IMG_0458.png|http://www.staging3.streamlineusa.com/wp-content/uploads/2020/05/IMG_0449.png|http://www.staging3.streamlineusa.com/wp-content/uploads/2020/05/IMG_0462.png|http://www.staging3.streamlineusa.com/wp-content/uploads/2020/05/IMG_0448.png|http://www.staging3.streamlineusa.com/wp-content/uploads/2020/05/IMG_0450.png|http://www.staging3.streamlineusa.com/wp-content/uploads/2020/05/IMG_0452.png|http://www.staging3.streamlineusa.com/wp-content/uploads/2020/05/IMG_0455.png | F6: Jackson Heights | G6: 2200 | H6: General Contractor | I6: Nathalie Akiya Design | J6: SWA Architecture | K6: Residential | L6: https://www.staging8.streamlineusa.com/residential/jackson-heights-townhouse/ | M6: https://www.staging8.streamlineusa.com/wp-content/uploads/2020/05/Jackson-Heights-Featured.png
A7: 2520 | B7: =VLOOKUP(D7, Current!C:C, 2, false) -> #REF! | C7: 24 | D7: Atrium Corporate Office | E7: http://www.staging3.streamlineusa.com/wp-content/uploads/2019/12/Streamline-USA-Atrium-5.65x4.11-1.jpg|http://www.staging3.streamlineusa.com/wp-content/uploads/2019/12/Streamline-USA-Atrium-3.69x1.91-1.jpg|http://www.staging3.streamlineusa.com/wp-content/uploads/2019/12/Streamline-USA-Atrium-1.71x1.90-1.jpg|http://www.staging3.streamlineusa.com/wp-content/uploads/2019/12/Streamline-USA-Atrium-8.0x2.25.jpg|http://www.staging3.streamlineusa.com/wp-content/uploads/2019/12/Streamline-USA-Atrium-1.71x1.91-1.jpg | F7: NoHo | G7: 5000 | H7: General Contractor + Millwork | I7: Sam Ben avraham | J7: Bang 3 Design | K7: Commercial | L7: https://www.staging8.streamlineusa.com/commercial/atrium-corporate-office/ | M7: https://www.staging8.streamlineusa.com/wp-content/uploads/2019/12/Streamline-USA-Atrium-5.65x4.11.jpg
A8: 439 | B8: =VLOOKUP(D8, Current!C:C, 2, false) -> #REF! | C8: 1 | D8: Boqueria Restaurant | E8: http://www.staging3.streamlineusa.com/wp-content/uploads/2019/12/Featured-1-scaled.jpg|http://www.staging3.streamlineusa.com/wp-content/uploads/2019/12/Boqueria_West40_0518_LizClayman_210-scaled.jpg|http://www.staging3.streamlineusa.com/wp-content/uploads/2019/12/Boqueria_West40_0518_LizClayman_211-scaled.jpg|http://www.staging3.streamlineusa.com/wp-content/uploads/2019/12/Boqueria_West40_0518_LizClayman_212-scaled.jpg|http://www.staging3.streamlineusa.com/wp-content/uploads/2019/12/Boqueria_West40_0518_LizClayman_197-scaled.jpg|http://www.staging3.streamlineusa.com/wp-content/uploads/2019/12/Boqueria_West40_0518_LizClayman_203-scaled.jpg|http://www.staging3.streamlineusa.com/wp-content/uploads/2019/12/Boqueria_West40_0518_LizClayman_206-scaled.jpg|http://www.staging3.streamlineusa.com/wp-content/uploads/2019/12/Boqueria_West40_0518_LizClayman_209-scaled.jpg|http://www.staging3.streamlineusa.com/wp-content/uploads/2019/12/Boqueria_West40_0518_LizClayman_003-scaled.jpg|http://www.staging3.streamlineusa.com/wp-content/uploads/2019/12/Boqueria_West40_0518_LizClayman_128-1-scaled.jpg | F8: Midtown | G8: 10500 | H8: General Contractor | I8: Studio Razavi | K8: Commercial | L8: https://www.staging8.streamlineusa.com/commercial/boqueria-restaurant/ | M8: https://www.staging8.streamlineusa.com/wp-content/uploads/2019/12/Featured-1-scaled.jpg
A9: 509 | B9: =VLOOKUP(D9, Current!C:C, 2, false) -> #REF! | C9: 9 | D9: Burger & Lobster | E9: http://www.staging3.streamlineusa.com/wp-content/uploads/2019/12/Burger-Lobster-Featured.jpg|http://www.staging3.streamlineusa.com/wp-content/uploads/2019/12/BURGERLOBSTER6.jpg|http://www.staging3.streamlineusa.com/wp-content/uploads/2019/12/BURGERLOBSTER2.jpg|http://www.staging3.streamlineusa.com/wp-content/uploads/2019/12/BURGERLOBSTER7.jpg|http://www.staging3.streamlineusa.com/wp-content/uploads/2019/12/BURGERLOBSTER3.jpg|http://www.staging3.streamlineusa.com/wp-content/uploads/2019/12/BURGERLOBSTER5.jpg|http://www.staging3.streamlineusa.com/wp-content/uploads/2019/12/BURGERLOBSTER4.jpg | F9: Bryant Park | G9: 8500 | H9: General Contractor + Millwork | I9: MZA Architecture | K9: Commercial | L9: https://www.staging8.streamlineusa.com/commercial/burger-lobster/ | M9: https://www.staging8.streamlineusa.com/wp-content/uploads/2019/12/BURGERLOBSTER3.jpg
A10: 552 | B10: =VLOOKUP(D10, Current!C:C, 2, false) -> #REF! | C10: 1 | D10: Duane Street Penthouse | E10: http://www.staging3.streamlineusa.com/wp-content/uploads/2022/02/20210310_129DuaneSt-3830-scaled.jpg|http://www.staging3.streamlineusa.com/wp-content/uploads/2022/02/20210310_129DuaneSt-3975-scaled.jpg|http://www.staging3.streamlineusa.com/wp-content/uploads/2022/02/20210310_129DuaneSt-3990-scaled.jpg|http://www.staging3.streamlineusa.com/wp-content/uploads/2022/02/20210310_129DuaneSt-3995-scaled.jpg|http://www.staging3.streamlineusa.com/wp-content/uploads/2022/02/20211021_129DuaneSt-8020-scaled.jpg|http://www.staging3.streamlineusa.com/wp-content/uploads/2022/02/20211021_129DuaneSt-8035-scaled.jpg|http://www.staging3.streamlineusa.com/wp-content/uploads/2022/02/20211021_129DuaneSt-8040-scaled.jpg|http://www.staging3.streamlineusa.com/wp-content/uploads/2022/02/20211021_129DuaneSt-8080-scaled.jpg|http://www.staging3.streamlineusa.com/wp-content/uploads/2022/02/20211021_129DuaneSt-8110-scaled.jpg|http://www.staging3.streamlineusa.com/wp-content/uploads/2022/02/20211021_129DuaneSt-8120-scaled.jpg|http://www.staging3.streamlineusa.com/wp-content/uploads/2022/02/20211021_129DuaneSt-8159-scaled.jpg | F10: Tribeca | G10: 4000 | H10: General Contractor | I10: Dean Winters and Diana Gomez | J10: SWA Architecture | K10: Residential | L10: https://www.staging8.streamlineusa.com/residential/duane-street-penthouse/ | M10: https://www.staging8.streamlineusa.com/wp-content/uploads/2022/02/20211021_129DuaneSt-8110-scaled.jpg
A11: 2345 | B11: =VLOOKUP(D11, Current!C:C, 2, false) -> #REF! | C11: 15 | D11: e63rd st Penthouse | E11: http://www.staging3.streamlineusa.com/wp-content/uploads/2019/12/Upper-East-Side-Penthouse-Featured.jpg|http://www.staging3.streamlineusa.com/wp-content/uploads/2019/12/Upper-East-Side-Penthouse-1.jpg|http://www.staging3.streamlineusa.com/wp-content/uploads/2019/12/Upper-East-Side-Penthouse-2.jpg|http://www.staging3.streamlineusa.com/wp-content/uploads/2019/12/Upper-East-Side-Penthouse-5.jpg|http://www.staging3.streamlineusa.com/wp-content/uploads/2019/12/Upper-East-Side-Penthouse-4.jpg | F11: Lenox Hill | G11: 1700 | H11: General Contractor + Millwork | I11: Jennifer Aderholdt Design | J11: SWA Architecture | K11: Residential | L11: https://www.staging8.streamlineusa.com/residential/upper-east-side-penthouse/ | M11: https://www.staging8.streamlineusa.com/wp-content/uploads/2019/12/Upper-East-Side-Penthouse-Featured.jpg
